Workbook

Sheet Versioning
B2: S.No. | C2: Version | D2: Description
B3: 1 | C3: 1 | D3: Default Template
B4: 2 | C4: 1.1 | D4: Added volumes sheet, Bandwidth calculator and few automations
B5: 3 | C5: 2 | D5: Major changes related to worker nodes calculation based on different Businessnext services Load Testing

Sheet Summary
B2: S.No. | C2: Sheet Name | D2: Description
B3: 1 | C3: Instructions | D3: This sheet contains Instructions to use Businessnext sizing template
B4: 2 | C4: Customer Volumes | D4: This sheet contains Application volumes received from customer or based on assumptions
B5: 3 | C5: Per Hour Volumes | D5: This sheet calculates per hour volumes as per volumes defined in Customer Volumes sheet to derive on services resource utilization
B6: 4 | C6: Services Calculation | D6: This sheet calculates resources required for each service based on volumes and formulas based on load testing results
B7: 5 | C7: Datasize-Parameters | D7: This sheet contains BUSINESSNEXT objects and their sizes based on records, fields and such parameters
B8: 6 | C8: Data size | D8: This sheet calculates Database size based on different objects
B9: 7 | C9: DMS size | D9: This sheet calculates DMS size based on different objects
B10: 8 | C10: Server size | D10: This sheet calculates Worker nodes and DB server size based on concurrency
B11: 9 | C11: Bandwidth Calculator | D11: This sheet calculates Bandwidth calculation as per users defined in Customer Volumes sheet
B12: 10 | C12: Additional Inputs | D12: This is blank sheet added for any additional inputs which are required for sizing
B13: 11 | C13: On-Prem Assumptions | D13: This sheet contains assumptions considered for On-prem hosting
B14: 12 | C14: Cloud Assumptions | D14: This sheet contains assumptions considered for Cloud hosting
B15: 13 | C15: SaaS Assumptions | D15: This sheet contains assumptions considered for SaaS hosting

Sheet Instructions
B2: Assumptions
B3: 1. Only Blue marked cell can be modified 2. The consitution of various objects is based as per the assumption of BUSINESSNEXT Objects Table 3. The default size of the system objects may vary depending on number of fields we wish to capture. This will only be determined after the study
B8: Sheet Name | C8: Topic/Table | D8: Description
B9: CustomerVolumes | C9: Customer Name | D9: Add customer name
C10: Assumptions for sizing | D10: Edit blue marked cells. Add sizing as per the established method
C11: Particulars for sizing | D11: Define what is considered for this bid
C12: Environments | D12: Define environments required
B13: PARAMETERS | C13: BUSINESSNEXT Objects | D13: "Business Or Similar Object" Cloumn values can be renamed according to RFP requirement
D14: "Has Flow Data" Column can be set Yes/No according to RFP Requirement
D15: Avg Size of Single Extended Field has been taken as 256 Bytes
D16: Total Object Storage for Single Record is extended for 2.5 times for flow data
C17: Database File Parameters | D17: Defined what is considered for calculation of database filed other than CRMNEXT Data tables
C18: What Constitutes a Object | D18: It defined that how single object record is associated with other objects in BUSINESSNEXT.
D19: Update the "Count" according to RFP Requirement
D20: Avg number of Extended Fields can be considered during calculation based on RFP requirement. Or use default 25
B21: DATA SIZE | C21: 1st Year, 2nd Year, 3rd Year, 4th Year, 5th Year | D21: Put the values of total columes for objects for calculation and below "Object Storage" table will give estimate of total storage in GB
B22: DMS DISK SIZE | C22: 1st Year, 2nd Year, 3rd Year, 4th Year, 5th Year | D22: Put the values of total columes for objects for calculation and below "File Storage" table will give estimate of total storage in GB
B23: SERVER SIZE | C23: 1st Year, 2nd Year, 3rd Year, 4th Year, 5th Year | D23: Only edit blue marked cells for integration and webapi cores for database server
B24: Bandwidth Calculator | C24: 2nd Year, 2nd Year, 3rd Year, 4th Year, 5th Year | D24: Bandwidth calculation as per users defined in Volumes sheet
B25: ADDITIONAL INPUTS | C25: Add any additional inputs which are required for sizing.

Sheet Customer Volumes
A1: Customer Name: Bandhan Bank
B2: S. No. | C2: Assumptions for sizing | D2: Y1 | E2: Y2 | F2: Y3 | G2: Y4 | H2: Y5 | I2: YoY Growth % | J2: Primary Owner | K2: Secondary Owner
B3: 1 | C3: Total Number of named Users | D3: 15500 | E3: =D3*(1+I3) -> 16275 | F3: =E3*(1+$I$3) -> 17088.75 | G3: =F3*(1+$I$3) -> 17943.188 | H3: =G3*(1+$I$3) -> 18840.347 | I3: 0.05 | J3: Pre-sales
B4: 2 | C4: Number of concurrent users | D4: =D3*0.3 -> 4650 | E4: =E3*0.3 -> 4882.5 | F4: =F3*0.3 -> 5126.625 | G4: =G3*0.3 -> 5382.9563 | H4: =H3*0.3 -> 5652.1041 | I4: 0.05 | J4: Pre-sales
B5: 3 | C5: Total no. of customers (Retail+Wholesale+SME/MSME) | D5: 25786541 | E5: =D5*(1+I5) -> 28365195 | F5: =E5*(1+I5) -> 31201715 | G5: =F5*(1+I5) -> 34321886 | H5: =G5*(1+I5) -> 37754075 | I5: 0.1 | J5: Pre-sales
B6: 4 | C6: Number of Activities per customer (meetings/ calls/ emails) | D6: 2 | E6: 2 | F6: 2 | G6: 2 | H6: 2 | J6: Pre-sales | K6: Assumption: 2 activities per customer
B7: 5 | C7: Number of Leads | D7: 10700000 | E7: =D7*(1+I7) -> 11770000 | F7: =E7*(1+I7) -> 12947000 | G7: =F7*(1+I7) -> 14241700 | H7: =G7*(1+I7) -> 15665870 | I7: 0.1 | J7: Pre-sales
B8: 6 | C8: Number of Activities per lead (meetings/ calls/ emails) | D8: 2 | E8: 2 | F8: 2 | G8: 2 | H8: 2 | J8: Pre-sales | K8: Assumption: 2 activities per Lead
B9: 7 | C9: Number of Service Requests (Cases) | D9: 20000 | E9: =D9*(1+I9) -> 21000 | F9: =E9*(1+I9) -> 22050 | G9: =F9*(1+I9) -> 23152.5 | H9: =G9*(1+I9) -> 24310.125 | I9: 0.05 | J9: Pre-sales
B10: 8 | C10: Number of Activities (meetings/ calls/ emails) per Service Request (Cases) | D10: 2 | E10: 2 | F10: 2 | G10: 2 | H10: 2 | J10: Pre-sales | K10: Assumption: 2 activities per Case
B11: 9 | C11: Number of Campaigns | D11: 50 | E11: 50 | F11: 50 | G11: 50 | H11: 50 | J11: Pre-sales | K11: Assumption: 1 Offer per customer
B12: 10 | C12: Number of Product Holdings per customer | D12: 1 | E12: 1 | F12: 1 | G12: 1 | H12: 1 | J12: Pre-sales | K12: Assumption: 1 PH per customer
B13: 11 | C13: Number of Concurrent Mobile Users | D13: 4050 | E13: =D13*(1+I13) -> 4252.5 | F13: =E13*(1+I13) -> 4465.125 | G13: =F13*(1+I13) -> 4688.3813 | H13: =G13*(1+I13) -> 4922.8003 | I13: 0.05 | J13: Pre-sales
B14: 12 | C14: Number of documents per customer | D14: 2 | E14: 2 | F14: 2 | G14: 2 | H14: 2 | J14: Pre-sales | K14: Assumption: 5 documents per Customer
B15: 13 | C15: Number of documents per Lead | D15: 2 | E15: 2 | F15: 2 | G15: 2 | H15: 2 | J15: Pre-sales | K15: Assumption: 5 documents per Lead
B16: 14 | C16: Number of documents per Service Request (Case) | D16: 1 | E16: 1 | F16: 1 | G16: 1 | H16: 1 | J16: Pre-sales | K16: Assumption: 5 documents per Case
B17: 15 | C17: Total Num of Documents | D17: =SUM(D14:D16) -> 5 | E17: =SUM(E14:E16) -> 5 | F17: =SUM(F14:F16) -> 5 | G17: =SUM(G14:G16) -> 5 | H17: =SUM(H14:H16) -> 5 | J17: Formula | K17: Assumption: Sum of above 3
B18: 16 | C18: Sized of document | D18: 256 KB | E18: 256 KB | F18: 256 KB | G18: 256 KB | H18: 256 KB | J18: Assumption | K18: Assumption: Default size 1 MB
B19: 17 | C19: Reports downloaded in PDF per user | D19: 1 | E19: 1 | F19: 1 | G19: 1 | H19: 1 | J19: Formula | K19: Assumption: 1 report per user per hour
B20: 18 | C20: Size of PDF | D20: 1 MB | E20: 1 MB | F20: 1 MB | G20: 1 MB | H20: 1 MB | J20: Assumption | K20: Assumption: Default size 1 MB
B21: 19 | C21: Number of Emails captured for Lead/Case creation | D21: =0.05*(D7+D9) -> 536000 | E21: =0.05*(E7+E9) -> 589550 | F21: =0.05*(F7+F9) -> 648452.5 | G21: =0.05*(G7+G9) -> 713242.62 | H21: =0.05*(H7+H9) -> 784509.01 | J21: Formula | K21: Assumption: 5% of total Lead & Case captured through Email syndication
B22: 20 | C22: Number of escalations | D22: =0.1*(D5+D7+D9) -> 3650654.1 | E22: =0.1*(E5+E7+E9) -> 4015619.5 | F22: =0.1*(F5+F7+F9) -> 4417076.5 | G22: =0.1*(G5+G7+G9) -> 4858673.9 | H22: =0.1*(H5+H7+H9) -> 5344425.5 | J22: Formula | K22: Assumption: 10% records escalation on Lead+Case+Accounts)
B23: 21 | C23: Number of Alerts | D23: =0.1*(D5+D7+D9) -> 3650654.1 | E23: =0.1*(E5+E7+E9) -> 4015619.5 | F23: =0.1*(F5+F7+F9) -> 4417076.5 | G23: =0.1*(G5+G7+G9) -> 4858673.9 | H23: =0.1*(H5+H7+H9) -> 5344425.5 | J23: Formula | K23: Assumption: 10% records alerts on Lead+Case+Accounts)
B24: 22 | C24: Number of Email/SMS | D24: =D7+D9 -> 10720000 | E24: =E7+E9 -> 11791000 | F24: =F7+F9 -> 12969050 | G24: =G7+G9 -> 14264852 | H24: =H7+H9 -> 15690180 | J24: Formula | K24: Assumption: 1 Email/SMS per Lead+Case
B25: 23 | C25: Rest API hits per day | D25: 5000 | E25: 5000 | F25: 5000 | G25: 5000 | H25: 5000 | J25: Pre-sales | K25: Assumption: Default assumption
B26: 24 | C26: Platform MS hits per day | J26: Formula | K26: Assumption: 1 hit for every Syndication, Escalation, Comm hit
B27: 25 | C27: Num of SLAs hit per day | D27: =0.01*(D5+D7+D9) -> 365065.41 | E27: =0.01*(E5+E7+E9) -> 401561.95 | F27: =0.01*(F5+F7+F9) -> 441707.65 | G27: =0.01*(G5+G7+G9) -> 485867.39 | H27: =0.01*(H5+H7+H9) -> 534442.55 | J27: Formula | K27: Assumption: 1% of Lead+Case+Customer
C28: Number of Contact per customer | D28: 2 | E28: 2 | F28: 2 | G28: 2 | H28: 2
C29: Average number of history records per object: Customer/Leads/Service Requests | D29: 3 | E29: 3 | F29: 3 | G29: 3 | H29: 3
B33: S.No. | C33: Particulars for sizing | J33: Inputs | K33: Comments, if any
B34: 1 | C34: Number of years for the required hardware sizing | J34: 5 Years
B35: 2 | C35: Type of Deployment | J35: SaaS
B36: 3 | C36: Infrastructure hosting platform | J36: Cloud
B37: 4 | C37: Choose preferred platform | J37: AWS
B38: 5 | C38: CRMnext Database | J38: Postgres
B39: 6 | C39: Is Reporting DB required? | J39: Yes
B41: S.No. | C41: Environments to be considered for Sizing | G41: Required | H41: Size equivalent to Prod | J41: Comments, if any
B42: 1 | C42: DC | G42: Yes | H42: NA
B43: 2 | C43: DR | G43: Yes | H43: 1
B44: 3 | C44: Pre-Prod | G44: Yes | H44: 0.5
...

Sheet Per Hour Volumes
B2: S. No. | C2: Assumptions for sizing | D2: Y1 | E2: Y2 | F2: Y3 | G2: Y4 | H2: Y5 | I2: YoY Growth % | J2: Primary Owner | K2: Secondary Owner
B3: 1 | C3: Total Number of named Users | D3: ='Customer Volumes'!D3 -> 15500 | E3: ='Customer Volumes'!E3 -> 16275 | F3: ='Customer Volumes'!F3 -> 17088.75 | G3: ='Customer Volumes'!G3 -> 17943.188 | H3: ='Customer Volumes'!H3 -> 18840.347 | I3: ='Customer Volumes'!I3 -> 0.05 | J3: Pre-sales
B4: 2 | C4: Number of concurrent users | D4: ='Customer Volumes'!D4 -> 4650 | E4: ='Customer Volumes'!E4 -> 4882.5 | F4: ='Customer Volumes'!F4 -> 5126.625 | G4: ='Customer Volumes'!G4 -> 5382.9563 | H4: ='Customer Volumes'!H4 -> 5652.1041 | I4: ='Customer Volumes'!I4 -> 0.05 | J4: Pre-sales
B5: 3 | C5: Total no. of customers | D5: ='Customer Volumes'!D5/200/8 -> 16116.588 | E5: ='Customer Volumes'!E5/200/8 -> 17728.247 | F5: ='Customer Volumes'!F5/200/8 -> 19501.072 | G5: ='Customer Volumes'!G5/200/8 -> 21451.179 | H5: ='Customer Volumes'!H5/200/8 -> 23596.297 | I5: ='Customer Volumes'!I5 -> 0.1 | J5: Pre-sales
B6: 4 | C6: Number of Activities per customer (meetings/ calls/ emails) | D6: 2 | E6: 2 | F6: 2 | G6: 2 | H6: 2 | J6: Pre-sales | K6: Assumption: 2 activities per customer
B7: 5 | C7: Number of Leads | D7: ='Customer Volumes'!D7/200/8 -> 6687.5 | E7: ='Customer Volumes'!E7/200/8 -> 7356.25 | F7: ='Customer Volumes'!F7/200/8 -> 8091.875 | G7: ='Customer Volumes'!G7/200/8 -> 8901.0625 | H7: ='Customer Volumes'!H7/200/8 -> 9791.1688 | J7: Pre-sales
B8: 6 | C8: Number of Activities per lead (meetings/ calls/ emails) | D8: 2 | E8: 2 | F8: 2 | G8: 2 | H8: 2 | J8: Pre-sales | K8: Assumption: 2 activities per Lead
B9: 7 | C9: Number of Cases | D9: ='Customer Volumes'!D9/200/8 -> 12.5 | E9: ='Customer Volumes'!E9/200/8 -> 13.125 | F9: ='Customer Volumes'!F9/200/8 -> 13.78125 | G9: ='Customer Volumes'!G9/200/8 -> 14.470313 | H9: ='Customer Volumes'!H9/200/8 -> 15.193828 | I9: 0.15 | J9: Pre-sales
B10: 8 | C10: Number of Activities (meetings/ calls/ emails) per Case | D10: 1 | E10: 1 | F10: 1 | G10: 1 | H10: 1 | J10: Pre-sales | K10: Assumption: 2 activities per Case
B11: 9 | C11: Number of Offers per Customer | D11: 1 | E11: 1 | F11: 1 | G11: 1 | H11: 1 | J11: Pre-sales | K11: Assumption: 1 Offer per customer
B12: 10 | C12: Number of Product Holdings per customer | D12: 1 | E12: 1 | F12: 1 | G12: 1 | H12: 1 | J12: Pre-sales | K12: Assumption: 1 PH per customer
B13: 11 | C13: Number of Concurrent Mobile Users | D13: 500 | E13: =D13*(1+I13) -> 525 | F13: =E13*(1+I13) -> 551.25 | G13: =F13*(1+I13) -> 578.8125 | H13: =G13*(1+I13) -> 607.75312 | I13: 0.05 | J13: Pre-sales
B14: 12 | C14: Number of documents per customer | D14: 2 | E14: 2 | F14: 2 | G14: 2 | H14: 2 | J14: Pre-sales | K14: Assumption: 5 documents per Customer
B15: 13 | C15: Number of documents per Lead | D15: 2 | E15: 2 | F15: 2 | G15: 2 | H15: 2 | J15: Pre-sales | K15: Assumption: 5 documents per Lead
B16: 14 | C16: Number of documents per Case | D16: 2 | E16: 2 | F16: 2 | G16: 2 | H16: 2 | J16: Pre-sales | K16: Assumption: 5 documents per Case
B17: 15 | C17: Total Num of Documents | D17: =(D5+D7+D9)*2 -> 45633.176 | E17: =(E5+E7+E9)*2 -> 50195.244 | F17: =(F5+F7+F9)*2 -> 55213.456 | G17: =(G5+G7+G9)*2 -> 60733.423 | H17: =(H5+H7+H9)*2 -> 66805.319 | J17: Formula | K17: Assumption: Sum of above 3
B18: 16 | C18: Size of document | D18: 1 MB | E18: 1 MB | F18: 1 MB | G18: 1 MB | H18: 1 MB | J18: Assumption | K18: Assumption: Default size 1 MB
B19: 17 | C19: Reports downloaded in PDF per hour | D19: =D4 -> 4650 | E19: =E4 -> 4882.5 | F19: =F4 -> 5126.625 | G19: =G4 -> 5382.9563 | H19: =H4 -> 5652.1041 | J19: Formula | K19: Assumption: 1 report per user per hour
B20: 18 | C20: Size of PDF | D20: 1 MB | E20: 1 MB | F20: 1 MB | G20: 1 MB | H20: 1 MB | J20: Assumption | K20: Assumption: Default size 1 MB
B21: 19 | C21: Number of Emails captured for Lead/Case creation | D21: =D5/10 -> 1611.6588 | E21: =E5/10 -> 1772.8247 | F21: =F5/10 -> 1950.1072 | G21: =G5/10 -> 2145.1179 | H21: =H5/10 -> 2359.6297 | J21: Formula | K21: Assumption: 5% of total Lead & Case captured through Email syndication
B22: 20 | C22: Number of escalations | D22: =0.1*(D7+D9+D5) -> 2281.6588 | E22: =0.1*(E7+E9+E5) -> 2509.7622 | F22: =0.1*(F7+F9+F5) -> 2760.6728 | G22: =0.1*(G7+G9+G5) -> 3036.6712 | H22: =0.1*(H7+H9+H5) -> 3340.2659 | J22: Formula | K22: Assumption: 10% records escalation on Lead+Case+Accounts)
B23: 21 | C23: Number of Alerts | D23: =0.1*(D7+D9+D5) -> 2281.6588 | E23: =0.1*(E7+E9+E5) -> 2509.7622 | F23: =0.1*(F7+F9+F5) -> 2760.6728 | G23: =0.1*(G7+G9+G5) -> 3036.6712 | H23: =0.1*(H7+H9+H5) -> 3340.2659 | J23: Formula | K23: Assumption: 10% records alerts on Lead+Case+Accounts)
B24: 22 | C24: Number of Email/SMS sent | D24: =D7+D9 -> 6700 | E24: =E7+E9 -> 7369.375 | F24: =F7+F9 -> 8105.6562 | G24: =G7+G9 -> 8915.5328 | H24: =H7+H9 -> 9806.3626 | J24: Formula | K24: Assumption: 1 Email/SMS per Lead+Case
B25: 23 | C25: Rest API hits per hour | D25: 100000 | E25: 100000 | F25: 100000 | G25: 100000 | H25: 100000 | J25: Pre-sales | K25: Assumption: Default assumption
B26: 24 | C26: Platform MS hits per hour | D26: =D21+D22+D24 -> 10593.318 | E26: =E21+E22+E24 -> 11651.962 | F26: =F21+F22+F24 -> 12816.436 | G26: =G21+G22+G24 -> 14097.322 | H26: =H21+H22+H24 -> 15506.258 | J26: Formula | K26: Assumption: 1 hit for every Syndication, Escalation, Comm hit
B27: 25 | C27: Num of SLAs hit per hour | D27: =0.1*(D7+D9+D5) -> 2281.6588 | E27: =0.1*(E7+E9+E5) -> 2509.7622 | F27: =0.1*(F7+F9+F5) -> 2760.6728 | G27: =0.1*(G7+G9+G5) -> 3036.6712 | H27: =0.1*(H7+H9+H5) -> 3340.2659 | J27: Formula | K27: Assumption: 1% of Lead+Case+Customer

Sheet Services Calculation
B2: Resources as per Load Testing | H2: Resources calculation as per per hour volumes
B3: Service | C3: Parameter | D3: Value | E3: vCPU | F3: Memory (GB) | H3: Y1 | I3: vCPU | J3: Memory (GB) | K3: Y2 | L3: vCPU | M3: Memory (GB) | N3: Y3 | O3: vCPU | P3: Memory (GB) | Q3: Y4 | R3: vCPU | S3: Memory (GB) | T3: Y5 | U3: vCPU | V3: Memory (GB) | W3: Remarks
B4: businessnext-app | C4: Number of concurrent users | D4: 100 | E4: 1.2 | F4: 2.2 | H4: ='Per Hour Volumes'!$D4 -> 4650 | I4: =H4/D4*E4 -> 55.8 | J4: =H4/D4*F4 -> 102.3 | K4: ='Per Hour Volumes'!E4 -> 4882.5 | L4: =K4/D4*E4 -> 58.59 | M4: =K4/D4*F4 -> 107.415 | N4: ='Per Hour Volumes'!F4 -> 5126.625 | O4: =N4/D4*E4 -> 61.5195 | P4: =N4/D4*F4 -> 112.78575 | Q4: ='Per Hour Volumes'!G4 -> 5382.9563 | R4: =Q4/D4*E4 -> 64.595475 | S4: =Q4/D4*F4 -> 118.42504 | T4: ='Per Hour Volumes'!H4 -> 5652.1041 | U4: =T4/D4*E4 -> 67.825249 | V4: =T4/D4*F4 -> 124.34629
B5: businessnext-mobile | C5: Actual mobile concurrency or 30% of app concurrency | D5: 100 | E5: 0.5 | F5: 2 | H5: ='Per Hour Volumes'!$D$13 -> 500 | I5: =H5/D5*E5 -> 2.5 | J5: =H5/D5*F5 -> 10 | K5: ='Per Hour Volumes'!$E$13 -> 525 | L5: =K5/D5*E5 -> 2.625 | M5: =K5/D5*F5 -> 10.5 | N5: ='Per Hour Volumes'!$F$13 -> 551.25 | O5: =N5/D5*E5 -> 2.75625 | P5: =N5/D5*F5 -> 11.025 | Q5: ='Per Hour Volumes'!$G$13 -> 578.8125 | R5: =Q5/D5*E5 -> 2.8940625 | S5: =Q5/D5*F5 -> 11.57625 | T5: ='Per Hour Volumes'!$H$13 -> 607.75312 | U5: =T5/D5*E5 -> 3.0387656 | V5: =T5/D5*F5 -> 12.155062
B6: API mobile case | C6: Actual mobile concurrency or 30% of app concurrency | D6: 100 | E6: 0.5 | F6: 2 | H6: ='Per Hour Volumes'!$D$13 -> 500 | I6: =H6/D6*E6 -> 2.5 | J6: =H6/D6*F6 -> 10 | K6: ='Per Hour Volumes'!$E$13 -> 525 | L6: =K6/D6*E6 -> 2.625 | M6: =K6/D6*F6 -> 10.5 | N6: ='Per Hour Volumes'!$F$13 -> 551.25 | O6: =N6/D6*E6 -> 2.75625 | P6: =N6/D6*F6 -> 11.025 | Q6: ='Per Hour Volumes'!$G$13 -> 578.8125 | R6: =Q6/D6*E6 -> 2.8940625 | S6: =Q6/D6*F6 -> 11.57625 | T6: ='Per Hour Volumes'!$H$13 -> 607.75312 | U6: =T6/D6*E6 -> 3.0387656 | V6: =T6/D6*F6 -> 12.155062
B7: RestAPI | C7: Rest API hits per hour | D7: 10000 | E7: 1 | F7: 1 | H7: ='Per Hour Volumes'!$D$25 -> 100000 | I7: =H7/D7*E7 -> 10 | J7: =H7/D7*F7 -> 10 | K7: ='Per Hour Volumes'!$E$25 -> 100000 | L7: =K7/D7*E7 -> 10 | M7: =K7/D7*F7 -> 10 | N7: ='Per Hour Volumes'!$F$25 -> 100000 | O7: =N7/D7*E7 -> 10 | P7: =N7/D7*F7 -> 10 | Q7: ='Per Hour Volumes'!$G$25 -> 100000 | R7: =Q7/D7*E7 -> 10 | S7: =Q7/D7*F7 -> 10 | T7: ='Per Hour Volumes'!$H$25 -> 100000 | U7: =T7/D7*E7 -> 10 | V7: =T7/D7*F7 -> 10
B8: Image processing | C8: 1 img per second | D8: 3600 | E8: 1 | F8: 1 | H8: 3600 | I8: =H8/D8*E8 -> 1 | J8: =H8/D8*F8 -> 1 | K8: 3600 | L8: =K8/D8*E8 -> 1 | M8: =K8/D8*F8 -> 1 | N8: 3600 | O8: =N8/D8*E8 -> 1 | P8: =N8/D8*F8 -> 1 | Q8: 3600 | R8: =Q8/D8*E8 -> 1 | S8: =Q8/D8*F8 -> 1 | T8: 3600 | U8: =T8/D8*E8 -> 1 | V8: =T8/D8*F8 -> 1
B9: PDF processing | C9: Reports downloaded in PDF per user | D9: 3600 | E9: 6 | F9: 6 | H9: ='Per Hour Volumes'!$D$19 -> 4650 | I9: =H9/D9*E9 -> 7.75 | J9: =H9/D9*F9 -> 7.75 | K9: ='Per Hour Volumes'!$E$19 -> 4882.5 | L9: =K9/D9*E9 -> 8.1375 | M9: =K9/D9*F9 -> 8.1375 | N9: ='Per Hour Volumes'!$F$19 -> 5126.625 | O9: =N9/D9*E9 -> 8.544375 | P9: =N9/D9*F9 -> 8.544375 | Q9: ='Per Hour Volumes'!$G$19 -> 5382.9563 | R9: =Q9/D9*E9 -> 8.9715938 | S9: =Q9/D9*F9 -> 8.9715938 | T9: ='Per Hour Volumes'!$H$19 -> 5652.1041 | U9: =T9/D9*E9 -> 9.4201734 | V9: =T9/D9*F9 -> 9.4201734
B10: Doc processing | C10: 1 Doc per second | D10: 3600 | E10: 1 | F10: 1 | H10: 3600 | I10: =H10/D10*E10 -> 1 | J10: =H10/D10*F10 -> 1 | K10: 3600 | L10: =K10/D10*E10 -> 1 | M10: =K10/D10*F10 -> 1 | N10: 3600 | O10: =N10/D10*E10 -> 1 | P10: =N10/D10*F10 -> 1 | Q10: 3600 | R10: =Q10/D10*E10 -> 1 | S10: =Q10/D10*F10 -> 1 | T10: 3600 | U10: =T10/D10*E10 -> 1 | V10: =T10/D10*F10 -> 1
B11: SLA ms | C11: Num of SLAs hit per hour | D11: 1000 | E11: 0.1 | F11: 0.1 | H11: ='Per Hour Volumes'!$D$27 -> 2281.6588 | I11: =H11/D11*E11 -> 0.22816588 | J11: =H11/D11*F11 -> 0.22816588 | K11: ='Per Hour Volumes'!$E$27 -> 2509.7622 | L11: =K11/D11*E11 -> 0.25097622 | M11: =K11/D11*F11 -> 0.25097622 | N11: ='Per Hour Volumes'!$F$27 -> 2760.6728 | O11: =N11/D11*E11 -> 0.27606728 | P11: =N11/D11*F11 -> 0.27606728 | Q11: ='Per Hour Volumes'!$G$27 -> 3036.6712 | R11: =Q11/D11*E11 -> 0.30366712 | S11: =Q11/D11*F11 -> 0.30366712 | T11: ='Per Hour Volumes'!$H$27 -> 3340.2659 | U11: =T11/D11*E11 -> 0.33402659 | V11: =T11/D11*F11 -> 0.33402659
B12: Script-utility | C12: One time activity | D12: 0 | E12: 0 | F12: 0 | H12: 0 | I12: 0 | J12: 0 | K12: 0 | L12: 0 | M12: 0 | N12: 0 | O12: 0 | P12: 0 | Q12: 0 | R12: 0 | S12: 0 | T12: 0 | U12: 0 | V12: 0
B13: Fscalation ms | C13: Number of escalations | D13: 1000 | E13: 0.1 | F13: 0.1 | H13: ='Per Hour Volumes'!$D$22 -> 2281.6588 | I13: =H13/D13*E13 -> 0.22816588 | J13: =H13/D13*F13 -> 0.22816588 | K13: ='Per Hour Volumes'!$E$22 -> 2509.7622 | L13: =K13/D13*E13 -> 0.25097622 | M13: =K13/D13*F13 -> 0.25097622 | N13: ='Per Hour Volumes'!$F$22 -> 2760.6728 | O13: =N13/D13*E13 -> 0.27606728 | P13: =N13/D13*F13 -> 0.27606728 | Q13: ='Per Hour Volumes'!$G$22 -> 3036.6712 | R13: =Q13/D13*E13 -> 0.30366712 | S13: =Q13/D13*F13 -> 0.30366712 | T13: ='Per Hour Volumes'!$H$22 -> 3340.2659 | U13: =T13/D13*E13 -> 0.33402659 | V13: =T13/D13*F13 -> 0.33402659
B14: Communication MS | C14: Number of Fmail/SMS sent | D14: 1000 | E14: 0.2 | F14: 0.5 | H14: ='Per Hour Volumes'!$D$24 -> 6700 | I14: =H14/D14*E14 -> 1.34 | J14: =H14/D14*F14 -> 3.35 | K14: ='Per Hour Volumes'!$E$24 -> 7369.375 | L14: =K14/D14*E14 -> 1.473875 | M14: =K14/D14*F14 -> 3.6846875 | N14: ='Per Hour Volumes'!$F$24 -> 8105.6562 | O14: =N14/D14*E14 -> 1.6211312 | P14: =N14/D14*F14 -> 4.0528281 | Q14: ='Per Hour Volumes'!$G$24 -> 8915.5328 | R14: =Q14/D14*E14 -> 1.7831066 | S14: =Q14/D14*F14 -> 4.4577664 | T14: ='Per Hour Volumes'!$H$24 -> 9806.3626 | U14: =T14/D14*E14 -> 1.9612725 | V14: =T14/D14*F14 -> 4.9031813
B15: Fscalation SDK | C15: Number of escalations | D15: 1000 | E15: 0.1 | F15: 0.1 | H15: ='Per Hour Volumes'!$D$22 -> 2281.6588 | I15: =H15/D15*E15 -> 0.22816588 | J15: =H15/D15*F15 -> 0.22816588 | K15: ='Per Hour Volumes'!$E$22 -> 2509.7622 | L15: =K15/D15*E15 -> 0.25097622 | M15: =K15/D15*F15 -> 0.25097622 | N15: ='Per Hour Volumes'!$F$22 -> 2760.6728 | O15: =N15/D15*E15 -> 0.27606728 | P15: =N15/D15*F15 -> 0.27606728 | Q15: ='Per Hour Volumes'!$G$22 -> 3036.6712 | R15: =Q15/D15*E15 -> 0.30366712 | S15: =Q15/D15*F15 -> 0.30366712 | T15: ='Per Hour Volumes'!$H$22 -> 3340.2659 | U15: =T15/D15*E15 -> 0.33402659 | V15: =T15/D15*F15 -> 0.33402659
B16: Platform MS | C16: Platform MS hits per hour | D16: 1000 | E16: 0.2 | F16: 0.4 | H16: ='Per Hour Volumes'!$D$26 -> 10593.318 | I16: =H16/D16*E16 -> 2.1186635 | J16: =H16/D16*F16 -> 4.2373271 | K16: ='Per Hour Volumes'!$E$26 -> 11651.962 | L16: =K16/D16*E16 -> 2.3303924 | M16: =K16/D16*F16 -> 4.6607848 | N16: ='Per Hour Volumes'!$F$26 -> 12816.436 | O16: =N16/D16*E16 -> 2.5632872 | P16: =N16/D16*F16 -> 5.1265745 | Q16: ='Per Hour Volumes'!$G$26 -> 14097.322 | R16: =Q16/D16*E16 -> 2.8194644 | S16: =Q16/D16*F16 -> 5.6389287 | T16: ='Per Hour Volumes'!$H$26 -> 15506.258 | U16: =T16/D16*E16 -> 3.1012516 | V16: =T16/D16*F16 -> 6.2025033
B17: Fmail Syndication SDK | C17: Number of Fmails captured for Lead/Case creation | D17: 1000 | E17: 0.2 | F17: 0.2 | H17: ='Per Hour Volumes'!$D$21 -> 1611.6588 | I17: =H17/D17*E17 -> 0.32233176 | J17: =H17/D17*F17 -> 0.32233176 | K17: ='Per Hour Volumes'!$E$21 -> 1772.8247 | L17: =K17/D17*E17 -> 0.35456494 | M17: =K17/D17*F17 -> 0.35456494 | N17: ='Per Hour Volumes'!$F$21 -> 1950.1072 | O17: =N17/D17*E17 -> 0.39002143 | P17: =N17/D17*F17 -> 0.39002143 | Q17: ='Per Hour Volumes'!$G$21 -> 2145.1179 | R17: =Q17/D17*E17 -> 0.42902358 | S17: =Q17/D17*F17 -> 0.42902358 | T17: ='Per Hour Volumes'!$H$21 -> 2359.6297 | U17: =T17/D17*E17 -> 0.47192593 | V17: =T17/D17*F17 -> 0.47192593
B18: Syndication Poller | C18: Number of Fmails captured for Lead/Case creation | D18: 1000 | E18: 0.1 | F18: 0.1 | H18: ='Per Hour Volumes'!$D$21 -> 1611.6588 | I18: =H18/D18*E18 -> 0.16116588 | J18: =H18/D18*F18 -> 0.16116588 | K18: ='Per Hour Volumes'!$E$21 -> 1772.8247 | L18: =K18/D18*E18 -> 0.17728247 | M18: =K18/D18*F18 -> 0.17728247 | N18: ='Per Hour Volumes'!$F$21 -> 1950.1072 | O18: =N18/D18*E18 -> 0.19501072 | P18: =N18/D18*F18 -> 0.19501072 | Q18: ='Per Hour Volumes'!$G$21 -> 2145.1179 | R18: =Q18/D18*E18 -> 0.21451179 | S18: =Q18/D18*F18 -> 0.21451179 | T18: ='Per Hour Volumes'!$H$21 -> 2359.6297 | U18: =T18/D18*E18 -> 0.23596297 | V18: =T18/D18*F18 -> 0.23596297
B19: Syndication Capture | C19: Number of Fmails captured for Lead/Case creation | D19: 1000 | E19: 0.1 | F19: 0.1 | H19: ='Per Hour Volumes'!$D$21 -> 1611.6588 | I19: =H19/D19*E19 -> 0.16116588 | J19: =H19/D19*F19 -> 0.16116588 | K19: ='Per Hour Volumes'!$E$21 -> 1772.8247 | L19: =K19/D19*E19 -> 0.17728247 | M19: =K19/D19*F19 -> 0.17728247 | N19: ='Per Hour Volumes'!$F$21 -> 1950.1072 | O19: =N19/D19*E19 -> 0.19501072 | P19: =N19/D19*F19 -> 0.19501072 | Q19: ='Per Hour Volumes'!$G$21 -> 2145.1179 | R19: =Q19/D19*E19 -> 0.21451179 | S19: =Q19/D19*F19 -> 0.21451179 | T19: ='Per Hour Volumes'!$H$21 -> 2359.6297 | U19: =T19/D19*E19 -> 0.23596297 | V19: =T19/D19*F19 -> 0.23596297
B20: Syndication Capture Worker | C20: Number of Fmails captured for Lead/Case creation | D20: 1000 | E20: 0.1 | F20: 0.1 | H20: ='Per Hour Volumes'!$D$21 -> 1611.6588 | I20: =H20/D20*E20 -> 0.16116588 | J20: =H20/D20*F20 -> 0.16116588 | K20: ='Per Hour Volumes'!$E$21 -> 1772.8247 | L20: =K20/D20*E20 -> 0.17728247 | M20: =K20/D20*F20 -> 0.17728247 | N20: ='Per Hour Volumes'!$F$21 -> 1950.1072 | O20: =N20/D20*E20 -> 0.19501072 | P20: =N20/D20*F20 -> 0.19501072 | Q20: ='Per Hour Volumes'!$G$21 -> 2145.1179 | R20: =Q20/D20*E20 -> 0.21451179 | S20: =Q20/D20*F20 -> 0.21451179 | T20: ='Per Hour Volumes'!$H$21 -> 2359.6297 | U20: =T20/D20*E20 -> 0.23596297 | V20: =T20/D20*F20 -> 0.23596297
B21: Integration | D21: 1 | E21: 8 | F21: 16 | H21: 1 | I21: =H21/D21*E21 -> 8 | J21: =H21/D21*F21 -> 16 | K21: 1 | L21: =K21/D21*E21 -> 8 | M21: =K21/D21*F21 -> 16 | N21: 1 | O21: =N21/D21*E21 -> 8 | P21: =N21/D21*F21 -> 16 | Q21: 1 | R21: =Q21/D21*E21 -> 8 | S21: =Q21/D21*F21 -> 16 | T21: 1 | U21: =T21/D21*E21 -> 8 | V21: =T21/D21*F21 -> 16 | W21: Static values as calculation not available
B22: XSLT Fusion | D22: 1 | E22: 1 | F22: 2 | H22: 1 | I22: =H22/D22*E22 -> 1 | J22: =H22/D22*F22 -> 2 | K22: 1 | L22: =K22/D22*E22 -> 1 | M22: =K22/D22*F22 -> 2 | N22: 1 | O22: =N22/D22*E22 -> 1 | P22: =N22/D22*F22 -> 2 | Q22: 1 | R22: =Q22/D22*E22 -> 1 | S22: =Q22/D22*F22 -> 2 | T22: 1 | U22: =T22/D22*E22 -> 1 | V22: =T22/D22*F22 -> 2
B23: Dynamic logging | D23: 1 | E23: 1 | F23: 2 | H23: 1 | I23: =H23/D23*E23 -> 1 | J23: =H23/D23*F23 -> 2 | K23: 1 | L23: =K23/D23*E23 -> 1 | M23: =K23/D23*F23 -> 2 | N23: 1 | O23: =N23/D23*E23 -> 1 | P23: =N23/D23*F23 -> 2 | Q23: 1 | R23: =Q23/D23*E23 -> 1 | S23: =Q23/D23*F23 -> 2 | T23: 1 | U23: =T23/D23*E23 -> 1 | V23: =T23/D23*F23 -> 2
H24: Total | I24: =SUM(I4:I23) -> 95.498991 | J24: =SUM(J4:J23) -> 171.12765 | L24: =SUM(L4:L23) -> 99.421108 | M24: =SUM(M4:M23) -> 178.53731 | O24: =SUM(O4:O23) -> 103.56405 | P24: =SUM(P4:P23) -> 186.36278 | R24: =SUM(R4:R23) -> 107.94132 | S24: =SUM(S4:S23) -> 194.62939 | U24: =SUM(U4:U23) -> 112.56737 | V24: =SUM(V4:V23) -> 203.36417
C26: Volumes
C27: Years | D27: Y1 | E27: Y2 | F27: Y3 | G27: Y4 | H27: Y5
C28: Total vCPU | D28: =ROUNDUP(I24,0) -> 96 | E28: =ROUNDUP(L24,0) -> 100 | F28: =ROUNDUP(O24,0) -> 104 | G28: =ROUNDUP(R24,0) -> 108 | H28: =ROUNDUP(U24,0) -> 113
C29: Total Memory(GB) | D29: =ROUNDUP(J24,0) -> 172 | E29: =ROUNDUP(M24,0) -> 179 | F29: =ROUNDUP(P24,0) -> 187 | G29: =S24 -> 194.62939 | H29: =ROUNDUP(V24,0) -> 204

Sheet Datasize-Parameters
B2: BUSINESSNEXT Objects | H2: ="What constitutes a "&C4 -> What constitutes a Account | L2: ="What constitues a "&C5 -> What constitues a Lead | P2: ="What constitutes a "&C6 -> What constitutes a Service Request (Case) | T2: Attachments per object
B3: System Object | C3: Business Or Similar Object | D3: Size per record | F3: Has Flow Data | I3: Count | J3: Total Size | M3: Count | N3: Total Size | Q3: Count | R3: Total Size | U3: Count | V3: Total Row Size
B4: Account | C4: Account | D4: 2 | E4: KB | F4: No | H4: Single Record | I4: 1 | J4: =I4*D4 -> 2 | L4: Single Record | M4: 1 | N4: =D5*M4 -> 2 | P4: Single Record | Q4: 1 | R4: =Q4*D6 -> 2 | T4: ='Datasize-Parameters'!$C$4 -> Account | U4: 2 | V4: =U4*$D$14 -> 0.2
B5: Lead | C5: Lead | D5: 2 | E5: KB | F5: Yes | H5: History Records | I5: 3 | J5: =I5*D4 -> 6 | L5: History Records | M5: 3 | N5: =M5*D5 -> 6 | P5: History Records | Q5: 3 | R5: =Q5*D6 -> 6 | T5: ='Datasize-Parameters'!$C$5 -> Lead | U5: 2 | V5: =U5*$D$14 -> 0.2
B6: Case | C6: Service Request (Case) | D6: 2 | E6: KB | F6: Yes | H6: ="Avg "&$C$11 -> Avg Activity | I6: 2 | J6: =IF($F$11="No",I6*$D$11,I6*$D$11*$D$18) -> 4 | L6: ="Avg "&$C$11 -> Avg Activity | M6: 2 | N6: =IF($F$11="No",M6*$D$11,M6*$D$11*$D$18) -> 4 | P6: ="Avg "&$C$11 -> Avg Activity | Q6: 2 | R6: =IF($F$11="No",Q6*$D$11,Q6*$D$11*$D$18) -> 4 | T6: ='Datasize-Parameters'!$C$6 -> Service Request (Case) | U6: 1 | V6: =U6*$D$14 -> 0.1
B7: Contract | C7: Campaign | D7: 2 | E7: KB | F7: No | H7: ="Avg "&$C$12 -> Avg Contact | I7: 2 | J7: =IF($F$12="No",I7*D12,I7*D12*$D$18) -> 4 | L7: Extended Fields | M7: 15 | N7: =ROUND(M7*$D$17,0) -> 4 | P7: Extended Fields | Q7: 10 | R7: =ROUND(Q7*$D$17,0) -> 3 | T7: ='Datasize-Parameters'!$C$7 -> Campaign | U7: 0 | V7: =U7*$D$14 -> 0
B8: Offer | C8: Offer | D8: 2 | E8: KB | F8: No | H8: Extended Fields | I8: 10 | J8: =ROUND(I8*$D$17,0) -> 3 | L8: Image Fields | M8: 0 | N8: =ROUND(M8*$D$26,0) -> 0 | P8: Image Fields | Q8: 0 | R8: =ROUND(Q8*$D$26,0) -> 0 | T8: ='Datasize-Parameters'!$C$8 -> Offer | U8: 0 | V8: =U8*$D$14 -> 0
B9: Opportunity | C9: Credit | D9: 2 | E9: KB | F9: No | H9: Image Fields | I9: 0 | J9: =ROUND(I9*$D$26,0) -> 0 | L9: Profile Images | M9: 0 | N9: =ROUND(M9*$D$25,0) -> 0 | P9: Profile Images | Q9: 0 | R9: =ROUND(Q9*$D$25,0) -> 0 | T9: ='Datasize-Parameters'!$C$9 -> Credit | U9: 0 | V9: =U9*$D$14 -> 0
B10: Holding | C10: Holding | D10: 2 | E10: KB | F10: No | H10: Profile Images | I10: 0 | J10: =ROUND(I10*$D$25,0) -> 0 | T10: ='Datasize-Parameters'!$C$10 -> Holding | U10: 0 | V10: =U10*$D$14 -> 0
B11: Activity | C11: Activity | D11: 2 | E11: KB | F11: No | T11: ='Datasize-Parameters'!$C$13 -> Facility | U11: 0 | V11: =U11*$D$14 -> 0
B12: Contact | C12: Contact | D12: 2 | E12: KB | F12: No | H12: =$C$4 &" Size" -> Account Size | J12: =SUM(J4:J10) -> 19 | L12: =$C$5 &" Size" -> Lead Size | N12: =SUM(N4:N11) -> 16 | P12: =C6&" Size" -> Service Request (Case) Size | R12: =SUM(R4:R11) -> 15
B13: Renewal/Payment | C13: Facility | D13: 2 | E13: KB | F13: No | H13: With Flow Data | J13: =IF($F$4="No", J12, J12*$D$18) -> 19 | L13: With Flow Data | N13: =IF($F$5="No", N12, N12*$D$18) -> 40 | P13: With Flow Data | R13: =IF($F$6="No", R12, R12*$D$18) -> 37.5 | T13: =G7&" Size" -> Size | V13: =SUM(V4:V12) -> 0.5
B14: Attachment DB Record | C14: Attachment DB Record | D14: 0.1 | E14: KB | F14: N/A | J14: Size in KB | N14: Size in KB | R14: Size in KB | V14: Size in KB
B15: History | C15: History | D15: As parent | E15: KB | F15: N/A
B16: Branches | C16: Branches | D16: 2 | E16: KB | F16: N/A | H16: ="What constitutes a "&C7 -> What constitutes a Campaign | L16: ="What constitutes a "&C8 -> What constitutes a Offer | P16: ="What constitutes a "&C9 -> What constitutes a Credit
B17: Extended Fields Avg Size | C17: Avg Size of Single Extended Field | D17: 0.25 | E17: KB | F17: N/A | I17: Count | J17: Total Size | M17: Count | N17: Total Size | Q17: Count | R17: Total Size
B18: Flow Data | C18: Multiple of estimated object size | D18: 2.5 | E18: times | F18: N/A | H18: Single Record | I18: 1 | J18: =I18*D7 -> 2 | L18: Single Record | M18: 0 | N18: =M18*D8 -> 0 | P18: Single Record | Q18: 0 | R18: =Q18*D9 -> 0
H19: History Records | I19: 3 | J19: =I19*D7 -> 6 | L19: History Records | M19: 0 | N19: =M19*D8 -> 0 | P19: History Records | Q19: 0 | R19: =Q19*D9 -> 0
B20: Set Parameters | H20: ="Avg "&$C$11 -> Avg Activity | I20: 2 | J20: =IF($F$11="No",I20*$D$11,I20*$D$11*$D$18) -> 4 | L20: ="Avg "&$C$11 -> Avg Activity | M20: 0 | N20: =IF($F$11="No",M20*$D$11,M20*$D$11*$D$18) -> 0 | P20: ="Avg "&$C$11 -> Avg Activity | Q20: 0 | R20: =IF($F$11="No",Q20*$D$11,Q20*$D$11*$D$18) -> 0
B21: System Object | D21: Size per record | H21: Extended Fields | I21: 0 | J21: =ROUND(I21*$D$17,0) -> 0 | L21: Extended Fields | M21: 0 | N21: =ROUND(M21*$D$17,0) -> 0 | P21: Extended Fields | Q21: 0 | R21: =ROUND(Q21*$D$17,0) -> 0
B22: SMS Log | D22: 0.1 | E22: KB | H22: Image Fields | I22: 0 | J22: =ROUND(I22*$D$26,0) -> 0 | L22: Image Fields | M22: 0 | N22: =ROUND(M22*$D$26,0) -> 0 | P22: Image Fields | Q22: 0 | R22: =ROUND(Q22*$D$26,0) -> 0
B23: Email Log | D23: 40 | E23: KB | H23: Profile Images | I23: 0 | J23: =ROUND(I23*$D$25,0) -> 0 | L23: Profile Images | M23: 0 | N23: =ROUND(M23*$D$25,0) -> 0 | P23: Profile Images | Q23: 0 | R23: =ROUND(Q23*$D$25,0) -> 0
B24: Attachment/File Size | D24: 256 | E24: KB
B25: Profile Image Field | D25: 5 | E25: KB | H25: =$C$7&" Size" -> Campaign Size | J25: =SUM(J18:J23) -> 12 | L25: =$C$8&" Size" -> Offer Size | N25: =SUM(N18:N23) -> 0 | P25: =$C$9&" Size" -> Credit Size | R25: =SUM(R18:R23) -> 0
B26: Image Field | D26: 5 | E26: KB | H26: With Flow Data | J26: =IF($F$7="No", J25, J25*$D$18) -> 12 | L26: With Flow Data | N26: =IF($F$8="No", N25, N25*$D$18) -> 0 | P26: With Flow Data | R26: =IF($F$9="No", R25, R25*$D$18) -> 0
J27: Size In KB | N27: Size In KB | R27: Size In KB
B28: Database File Parameters
B29: Temp DB | C29: 0.15 | D29: Of Object Storage | H29: ="What constitutes of "&$C$10 -> What constitutes of Holding | L29: ="What constitutes of "&$C$13 -> What constitutes of Facility
B30: Transaciton Log: | C30: 0.2 | D30: Of Object Storage | I30: Count | J30: Total Size | M30: Count | N30: Total Size
B31: Integration Area | C31: 0.2 | D31: Of Object Storage | H31: Single Record | I31: 1 | J31: =I31*D10 -> 2 | L31: Single Record | M31: 0 | N31: =M31*D13 -> 0
B32: Primary FG/TS | C32: 0.2 | D32: Of Object Storage | H32: History Record | I32: 3 | J32: =I32*D10 -> 6 | L32: History Record | M32: 0 | N32: =M32*D13 -> 0
B33: Temp DB log | C33: 0.25 | D33: Of Temp DB | H33: ="Avg "&$C$11 -> Avg Activity | I33: 0 | J33: =IF($F$11="No",I33*$D$11,I33*$D$11*$D$18) -> 0 | L33: ="Avg "&$C$11 -> Avg Activity | M33: 0 | N33: =IF($F$11="No",M33*$D$11,M33*$D$11*$D$18) -> 0
B34: CRMNEXT Logs | C34: 0.1 | D34: Of Object Storage | H34: Extended Fields | I34: 0 | J34: =ROUND(I34*$D$17,0) -> 0 | L34: Extended Fields | M34: 0 | N34: =ROUND(M34*$D$17,0) -> 0
H35: Image Fields | I35: 0 | J35: =ROUND(I35*$D$26,0) -> 0 | L35: Image Fields | M35: 0 | N35: =ROUND(M35*$D$26,0) -> 0
B36: CRMNEXT Logs: Schema Log, API Logs etc. should be purged quartely basis or earlier as it may impact the storage sizing heavily | H36: Profile Images | I36: 0 | J36: =ROUND(I36*$D$25,0) -> 0 | L36: Profile Images | M36: 0 | N36: =ROUND(M36*$D$25,0) -> 0
H38: =$C$10&" Size" -> Holding Size | J38: =SUM(J31:J36) -> 8 | L38: =$C$13&" Size" -> Facility Size | N38: =SUM(N31:N36) -> 0
H39: With Flow Data | J39: =IF($F$10="No", J38, J38*$D$18) -> 8 | L39: With Flow Data | N39: =IF($F$13="No", N38, N38*$D$18) -> 0
J40: Size In KB | N40: Size In KB

Sheet Data size
B2: 1st Year | F2: 2nd Year | J2: 3rd Year | N2: 4th Year | R2: 5th Year
B3: Object Storage | C3: Total Count | D3: Size | F3: Object Storage | G3: Total Count | H3: Size | J3: Object Storage | K3: Total Count | L3: Size | N3: Object Storage | O3: Total Count | P3: Size | R3: Object Storage | S3: Total Count | T3: Size
B5: ='Datasize-Parameters'!$C$4 -> Account | C5: ='Customer Volumes'!D5 -> 25786541 | D5: =C5*'Datasize-Parameters'!$J$13/(1024*1024) -> 467.24728 | F5: ='Datasize-Parameters'!$C$4 -> Account | G5: ='Customer Volumes'!E5 -> 28365195 | H5: =G5*'Datasize-Parameters'!$J$13/(1024*1024) -> 513.972 | J5: ='Datasize-Parameters'!$C$4 -> Account | K5: ='Customer Volumes'!F5 -> 31201715 | L5: =K5*'Datasize-Parameters'!$J$13/(1024*1024) -> 565.3692 | N5: ='Datasize-Parameters'!$C$4 -> Account | O5: ='Customer Volumes'!G5 -> 34321886 | P5: =O5*'Datasize-Parameters'!$J$13/(1024*1024) -> 621.90612 | R5: ='Datasize-Parameters'!$C$4 -> Account | S5: ='Customer Volumes'!H5 -> 37754075 | T5: =S5*'Datasize-Parameters'!$J$13/(1024*1024) -> 684.09674
B6: ='Datasize-Parameters'!$C$5 -> Lead | C6: ='Customer Volumes'!D7 -> 10700000 | D6: =C6*'Datasize-Parameters'!$N$13/(1024*1024) -> 408.17261 | F6: ='Datasize-Parameters'!$C$5 -> Lead | G6: ='Customer Volumes'!E7 -> 11770000 | H6: =G6*'Datasize-Parameters'!$N$13/(1024*1024) -> 448.98987 | J6: ='Datasize-Parameters'!$C$5 -> Lead | K6: ='Customer Volumes'!F7 -> 12947000 | L6: =K6*'Datasize-Parameters'!$N$13/(1024*1024) -> 493.88885 | N6: ='Datasize-Parameters'!$C$5 -> Lead | O6: ='Customer Volumes'!G7 -> 14241700 | P6: =O6*'Datasize-Parameters'!$N$13/(1024*1024) -> 543.27774 | R6: ='Datasize-Parameters'!$C$5 -> Lead | S6: ='Customer Volumes'!H7 -> 15665870 | T6: =S6*'Datasize-Parameters'!$N$13/(1024*1024) -> 597.60551
B7: ='Datasize-Parameters'!$C$6 -> Service Request (Case) | C7: ='Customer Volumes'!D9 -> 20000 | D7: =C7*'Datasize-Parameters'!$R$13/(1024*1024) -> 0.71525574 | F7: ='Datasize-Parameters'!$C$6 -> Service Request (Case) | G7: ='Customer Volumes'!E9 -> 21000 | H7: =G7*'Datasize-Parameters'!$R$13/(1024*1024) -> 0.75101852 | J7: ='Datasize-Parameters'!$C$6 -> Service Request (Case) | K7: ='Customer Volumes'!F9 -> 22050 | L7: =K7*'Datasize-Parameters'!$R$13/(1024*1024) -> 0.78856945 | N7: ='Datasize-Parameters'!$C$6 -> Service Request (Case) | O7: ='Customer Volumes'!G9 -> 23152.5 | P7: =O7*'Datasize-Parameters'!$R$13/(1024*1024) -> 0.82799792 | R7: ='Datasize-Parameters'!$C$6 -> Service Request (Case) | S7: ='Customer Volumes'!H9 -> 24310.125 | T7: =S7*'Datasize-Parameters'!$R$13/(1024*1024) -> 0.86939782
B8: ='Datasize-Parameters'!$C$7 -> Campaign | C8: ='Customer Volumes'!D11 -> 50 | D8: =C8*'Datasize-Parameters'!$J$26/(1024*1024) -> 0.00057220459 | F8: ='Datasize-Parameters'!$C$7 -> Campaign | G8: ='Customer Volumes'!E11 -> 50 | H8: =G8*'Datasize-Parameters'!$J$26/(1024*1024) -> 0.00057220459 | J8: ='Datasize-Parameters'!$C$7 -> Campaign | K8: ='Customer Volumes'!F11 -> 50 | L8: =K8*'Datasize-Parameters'!$J$26/(1024*1024) -> 0.00057220459 | N8: ='Datasize-Parameters'!$C$7 -> Campaign | O8: ='Customer Volumes'!G11 -> 50 | P8: =O8*'Datasize-Parameters'!$J$26/(1024*1024) -> 0.00057220459 | R8: ='Datasize-Parameters'!$C$7 -> Campaign | S8: 0 | T8: =S8*'Datasize-Parameters'!$J$26/(1024*1024) -> 0
B9: ='Datasize-Parameters'!$C$8 -> Offer | C9: 0 | D9: =C9*'Datasize-Parameters'!$N$26/(1024*1024) -> 0 | F9: ='Datasize-Parameters'!$C$8 -> Offer | G9: 0 | H9: =G9*'Datasize-Parameters'!$N$26/(1024*1024) -> 0 | J9: ='Datasize-Parameters'!$C$8 -> Offer | K9: 0 | L9: =K9*'Datasize-Parameters'!$N$26/(1024*1024) -> 0 | N9: ='Datasize-Parameters'!$C$8 -> Offer | O9: 0 | P9: =O9*'Datasize-Parameters'!$N$26/(1024*1024) -> 0 | R9: ='Datasize-Parameters'!$C$8 -> Offer | S9: 0 | T9: =S9*'Datasize-Parameters'!$N$26/(1024*1024) -> 0
B10: ='Datasize-Parameters'!$C$9 -> Credit | C10: 0 | D10: =C10*'Datasize-Parameters'!$R$26/(1024*1024) -> 0 | F10: ='Datasize-Parameters'!$C$9 -> Credit | G10: 0 | H10: =G10*'Datasize-Parameters'!$R$26/(1024*1024) -> 0 | J10: ='Datasize-Parameters'!$C$9 -> Credit | K10: 0 | L10: =K10*'Datasize-Parameters'!$R$26/(1024*1024) -> 0 | N10: ='Datasize-Parameters'!$C$9 -> Credit | O10: 0 | P10: =O10*'Datasize-Parameters'!$R$26/(1024*1024) -> 0 | R10: ='Datasize-Parameters'!$C$9 -> Credit | S10: 0 | T10: =S10*'Datasize-Parameters'!$R$26/(1024*1024) -> 0
B11: ='Datasize-Parameters'!$C$10 -> Holding | C11: ='Customer Volumes'!D5*'Customer Volumes'!D12 -> 25786541 | D11: =C11*'Datasize-Parameters'!$J$39/(1024*1024) -> 196.73569 | F11: ='Datasize-Parameters'!$C$10 -> Holding | G11: ='Customer Volumes'!E5*'Customer Volumes'!E12 -> 28365195 | H11: =G11*'Datasize-Parameters'!$J$39/(1024*1024) -> 216.40926 | J11: ='Datasize-Parameters'!$C$10 -> Holding | K11: ='Customer Volumes'!F5*'Customer Volumes'!F12 -> 31201715 | L11: =K11*'Datasize-Parameters'!$J$39/(1024*1024) -> 238.05019 | N11: ='Datasize-Parameters'!$C$10 -> Holding | O11: ='Customer Volumes'!G5*'Customer Volumes'!G12 -> 34321886 | P11: =O11*'Datasize-Parameters'!$J$39/(1024*1024) -> 261.85521 | R11: ='Datasize-Parameters'!$C$10 -> Holding | S11: ='Customer Volumes'!H5*'Customer Volumes'!H12 -> 37754075 | T11: =S11*'Datasize-Parameters'!$J$39/(1024*1024) -> 288.04073
B12: ='Datasize-Parameters'!$C$13 -> Facility | C12: 0 | D12: =C12*'Datasize-Parameters'!$N$39/(1024*1024) -> 0 | F12: ='Datasize-Parameters'!$C$13 -> Facility | G12: 0 | H12: =G12*'Datasize-Parameters'!$N$39/(1024*1024) -> 0 | J12: ='Datasize-Parameters'!$C$13 -> Facility | K12: 0 | L12: =K12*'Datasize-Parameters'!$N$39/(1024*1024) -> 0 | N12: ='Datasize-Parameters'!$C$13 -> Facility | O12: 0 | P12: =O12*'Datasize-Parameters'!$N$39/(1024*1024) -> 0 | R12: ='Datasize-Parameters'!$C$13 -> Facility | S12: 0 | T12: =S12*'Datasize-Parameters'!$N$39/(1024*1024) -> 0
B13: SMS Log | C13: 0 | D13: =C13*'Datasize-Parameters'!$D$22/(1024*1024) -> 0 | F13: SMS Log | G13: 0 | H13: =G13*'Datasize-Parameters'!$D$22/(1024*1024) -> 0 | J13: SMS Log | K13: 0 | L13: =K13*'Datasize-Parameters'!$D$22/(1024*1024) -> 0 | N13: SMS Log | O13: 0 | P13: =O13*'Datasize-Parameters'!$D$22/(1024*1024) -> 0 | R13: SMS Log | S13: 0 | T13: =S13*'Datasize-Parameters'!$D$22/(1024*1024) -> 0
B14: Email Log | C14: 0 | D14: =C14*'Datasize-Parameters'!$D$23/(1024*1024) -> 0 | F14: Email Log | G14: 0 | H14: =G14*'Datasize-Parameters'!$D$23/(1024*1024) -> 0 | J14: Email Log | K14: 0 | L14: =K14*'Datasize-Parameters'!$D$23/(1024*1024) -> 0 | N14: Email Log | O14: 0 | P14: =O14*'Datasize-Parameters'!$D$23/(1024*1024) -> 0 | R14: Email Log | S14: 0 | T14: =S14*'Datasize-Parameters'!$D$23/(1024*1024) -> 0
B15: Attachment Table | C15: =C5*0.3+C6*0.3+C7 -> 10965962 | D15: =C15*'Datasize-Parameters'!$V$13/(1024*1024) -> 5.2289783 | F15: Attachment Table | G15: =G5*0.3+G6*0.3+G7 -> 12061559 | H15: =G15*'Datasize-Parameters'!$V$13/(1024*1024) -> 5.7513993 | J15: Attachment Table | K15: =K5*0.3+K6*0.3+K7 -> 13266664 | L15: =K15*'Datasize-Parameters'!$V$13/(1024*1024) -> 6.3260385 | N15: Attachment Table | O15: =O5*0.3+O6*0.3+O7 -> 14592228 | P15: =O15*'Datasize-Parameters'!$V$13/(1024*1024) -> 6.9581167 | R15: Attachment Table | S15: =S5*0.3+S6*0.3+S7 -> 16050294 | T15: =S15*'Datasize-Parameters'!$V$13/(1024*1024) -> 7.6533764
B17: Total Object Storage | D17: =SUM(D5:D15) -> 1078.1004 | F17: Total Object Storage | H17: =SUM(H5:H15) -> 1185.8741 | J17: Total Object Storage | L17: =SUM(L5:L15) -> 1304.4234 | N17: Total Object Storage | P17: =SUM(P5:P15) -> 1434.8258 | R17: Total Object Storage | T17: =SUM(T5:T15) -> 1578.2658
D18: Size in GB | H18: Size in GB | L18: Size in GB | P18: Size in GB | T18: Size in GB
B20: Final Database Size (GB) | F20: Final Database Size (GB) | J20: Final Database Size (GB) | N20: Final Database Size (GB) | R20: Final Database Size (GB)
B22: Object Storage | D22: =D17 -> 1078.1004 | F22: Object Storage | H22: =H17 -> 1185.8741 | J22: Object Storage | L22: =L17 -> 1304.4234 | N22: Object Storage | P22: =P17 -> 1434.8258 | R22: Object Storage | T22: =T17 -> 1578.2658
B23: Temp DB | D23: =D22*'Datasize-Parameters'!$C$29 -> 161.71506 | F23: Temp DB | H23: =H22*'Datasize-Parameters'!$C$29 -> 177.88112 | J23: Temp DB | L23: =L22*'Datasize-Parameters'!$C$29 -> 195.66351 | N23: Temp DB | P23: =P22*'Datasize-Parameters'!$C$29 -> 215.22386 | R23: Temp DB | T23: =T22*'Datasize-Parameters'!$C$29 -> 236.73986
B24: Transaciton Log: | D24: =D22*'Datasize-Parameters'!$C$30 -> 215.62008 | F24: Transaciton Log: | H24: =H22*'Datasize-Parameters'!$C$30 -> 237.17483 | J24: Transaciton Log: | L24: =L22*'Datasize-Parameters'!$C$30 -> 260.88469 | N24: Transaciton Log: | P24: =P22*'Datasize-Parameters'!$C$30 -> 286.96515 | R24: Transaciton Log: | T24: =T22*'Datasize-Parameters'!$C$30 -> 315.65315
B25: Integration Area | D25: =D22*'Datasize-Parameters'!$C$31 -> 215.62008 | F25: Integration Area | H25: =H22*'Datasize-Parameters'!$C$31 -> 237.17483 | J25: Integration Area | L25: =L22*'Datasize-Parameters'!$C$31 -> 260.88469 | N25: Integration Area | P25: =P22*'Datasize-Parameters'!$C$31 -> 286.96515 | R25: Integration Area | T25: =T22*'Datasize-Parameters'!$C$31 -> 315.65315
B26: Primary Filegroup /Tablespace | D26: =D22*'Datasize-Parameters'!$C$32 -> 215.62008 | F26: Primary Filegroup /Tablespace | H26: =H22*'Datasize-Parameters'!$C$32 -> 237.17483 | J26: Primary Filegroup /Tablespace | L26: =L22*'Datasize-Parameters'!$C$32 -> 260.88469 | N26: Primary Filegroup /Tablespace | P26: =P22*'Datasize-Parameters'!$C$32 -> 286.96515 | R26: Primary Filegroup /Tablespace | T26: =T22*'Datasize-Parameters'!$C$32 -> 315.65315
B27: Temp DB Log | D27: =D23*'Datasize-Parameters'!$C$33 -> 40.428764 | F27: Temp DB Log | H27: =H23*'Datasize-Parameters'!$C$33 -> 44.47028 | J27: Temp DB Log | L27: =L23*'Datasize-Parameters'!$C$33 -> 48.915879 | N27: Temp DB Log | P27: =P23*'Datasize-Parameters'!$C$33 -> 53.805966 | R27: Temp DB Log | T27: =T23*'Datasize-Parameters'!$C$33 -> 59.184966
B28: CRMNEXT Log | D28: =D22*'Datasize-Parameters'!$C$34 -> 107.81004 | F28: CRMNEXT Log | H28: =H22*'Datasize-Parameters'!$C$34 -> 118.58741 | J28: CRMNEXT Log | L28: =L22*'Datasize-Parameters'!$C$34 -> 130.44234 | N28: CRMNEXT Log | P28: =P22*'Datasize-Parameters'!$C$34 -> 143.48258 | R28: CRMNEXT Log | T28: =T22*'Datasize-Parameters'!$C$34 -> 157.82658
B30: Total: 1st year | D30: =SUM(D22:D28) -> 2034.9145 | F30: Total: 2nd year | H30: =SUM(H22:H28) -> 2238.3374 | J30: Total: 3rd year | L30: =SUM(L22:L28) -> 2462.0992 | N30: Total: 4th year | P30: =SUM(P22:P28) -> 2708.2336 | R30: Total: 5th year | T30: =SUM(T22:T28) -> 2978.9766
B31: Usable Space | D31: GB | F31: Usable Space | H31: GB | J31: Usable Space | L31: GB | N31: Usable Space | P31: GB | R31: Usable Space | T31: GB

Sheet DMS size
B2: 1st Year | F2: 2nd Year | J2: 3rd Year | N2: 4th Year | R2: 5th Year
B3: File Disk Storage | C3: File Count | D3: Size | F3: File Disk Storage | G3: File Count | H3: Size | J3: Object Storage | K3: File Count | L3: Size | N3: Object Storage | O3: File Count | P3: Size | R3: Object Storage | S3: File Count | T3: Size
B5: ='Datasize-Parameters'!$C$4 -> Account | C5: ='Customer Volumes'!D5*'Customer Volumes'!D14*0.3 -> 15471925 | D5: =C5*'Datasize-Parameters'!$D$24/(1024*1024) -> 3777.3253 | F5: ='Datasize-Parameters'!$C$4 -> Account | G5: ='Customer Volumes'!E5*'Customer Volumes'!E14*0.3 -> 17019117 | H5: =G5*'Datasize-Parameters'!$D$24/(1024*1024) -> 4155.0579 | J5: ='Datasize-Parameters'!$C$4 -> Account | K5: ='Customer Volumes'!F5*'Customer Volumes'!F14*0.3 -> 18721029 | L5: =K5*'Datasize-Parameters'!$D$24/(1024*1024) -> 4570.5637 | N5: ='Datasize-Parameters'!$C$4 -> Account | O5: ='Customer Volumes'!G5*'Customer Volumes'!G14*0.3 -> 20593132 | P5: =O5*'Datasize-Parameters'!$D$24/(1024*1024) -> 5027.62 | R5: ='Datasize-Parameters'!$C$4 -> Account | S5: ='Customer Volumes'!H5*'Customer Volumes'!H14*0.3 -> 22652445 | T5: =S5*'Datasize-Parameters'!$D$24/(1024*1024) -> 5530.382
B6: ='Datasize-Parameters'!$C$5 -> Lead | C6: ='Customer Volumes'!D7*'Customer Volumes'!D15*0.3 -> 6420000 | D6: =C6*'Datasize-Parameters'!$D$24/(1024*1024) -> 1567.3828 | F6: ='Datasize-Parameters'!$C$5 -> Lead | G6: ='Customer Volumes'!E7*'Customer Volumes'!E15*0.3 -> 7062000 | H6: =G6*'Datasize-Parameters'!$D$24/(1024*1024) -> 1724.1211 | J6: ='Datasize-Parameters'!$C$5 -> Lead | K6: ='Customer Volumes'!F7*'Customer Volumes'!F15*0.3 -> 7768200 | L6: =K6*'Datasize-Parameters'!$D$24/(1024*1024) -> 1896.5332 | N6: ='Datasize-Parameters'!$C$5 -> Lead | O6: ='Customer Volumes'!G7*'Customer Volumes'!G15*0.3 -> 8545020 | P6: =O6*'Datasize-Parameters'!$D$24/(1024*1024) -> 2086.1865 | R6: ='Datasize-Parameters'!$C$5 -> Lead | S6: ='Customer Volumes'!H7*'Customer Volumes'!H15*0.3 -> 9399522 | T6: =S6*'Datasize-Parameters'!$D$24/(1024*1024) -> 2294.8052
B7: ='Datasize-Parameters'!$C$6 -> Service Request (Case) | C7: ='Customer Volumes'!D9*'Customer Volumes'!D16 -> 20000 | D7: =C7*'Datasize-Parameters'!$D$24/(1024*1024) -> 4.8828125 | F7: ='Datasize-Parameters'!$C$6 -> Service Request (Case) | G7: ='Customer Volumes'!E9*'Customer Volumes'!E16 -> 21000 | H7: =G7*'Datasize-Parameters'!$D$24/(1024*1024) -> 5.1269531 | J7: ='Datasize-Parameters'!$C$6 -> Service Request (Case) | K7: ='Customer Volumes'!F9*'Customer Volumes'!F16 -> 22050 | L7: =K7*'Datasize-Parameters'!$D$24/(1024*1024) -> 5.3833008 | N7: ='Datasize-Parameters'!$C$6 -> Service Request (Case) | O7: ='Customer Volumes'!G9*'Customer Volumes'!G16 -> 23152.5 | P7: =O7*'Datasize-Parameters'!$D$24/(1024*1024) -> 5.6524658 | R7: ='Datasize-Parameters'!$C$6 -> Service Request (Case) | S7: ='Customer Volumes'!H9*'Customer Volumes'!H16 -> 24310.125 | T7: =S7*'Datasize-Parameters'!$D$24/(1024*1024) -> 5.9350891
B8: ='Datasize-Parameters'!$C$7 -> Campaign | C8: 0 | D8: =C8*'Datasize-Parameters'!$D$24/(1024*1024) -> 0 | F8: ='Datasize-Parameters'!$C$7 -> Campaign | G8: 0 | H8: =G8*'Datasize-Parameters'!$D$24/(1024*1024) -> 0 | J8: ='Datasize-Parameters'!$C$7 -> Campaign | K8: 0 | L8: =K8*'Datasize-Parameters'!$D$24/(1024*1024) -> 0 | N8: ='Datasize-Parameters'!$C$7 -> Campaign | O8: 0 | P8: =O8*'Datasize-Parameters'!$D$24/(1024*1024) -> 0 | R8: ='Datasize-Parameters'!$C$7 -> Campaign | S8: 0 | T8: =S8*'Datasize-Parameters'!$D$24/(1024*1024) -> 0
B9: ='Datasize-Parameters'!$C$8 -> Offer | C9: 0 | D9: =C9*'Datasize-Parameters'!$D$24/(1024*1024) -> 0 | F9: ='Datasize-Parameters'!$C$8 -> Offer | G9: 0 | H9: =G9*'Datasize-Parameters'!$D$24/(1024*1024) -> 0 | J9: ='Datasize-Parameters'!$C$8 -> Offer | K9: 0 | L9: =K9*'Datasize-Parameters'!$D$24/(1024*1024) -> 0 | N9: ='Datasize-Parameters'!$C$8 -> Offer | O9: 0 | P9: =O9*'Datasize-Parameters'!$D$24/(1024*1024) -> 0 | R9: ='Datasize-Parameters'!$C$8 -> Offer | S9: 0 | T9: =S9*'Datasize-Parameters'!$D$24/(1024*1024) -> 0
B10: ='Datasize-Parameters'!$C$9 -> Credit | C10: 0 | D10: =C10*'Datasize-Parameters'!$D$24/(1024*1024) -> 0 | F10: ='Datasize-Parameters'!$C$9 -> Credit | G10: 0 | H10: =G10*'Datasize-Parameters'!$D$24/(1024*1024) -> 0 | J10: ='Datasize-Parameters'!$C$9 -> Credit | K10: 0 | L10: =K10*'Datasize-Parameters'!$D$24/(1024*1024) -> 0 | N10: ='Datasize-Parameters'!$C$9 -> Credit | O10: 0 | P10: =O10*'Datasize-Parameters'!$D$24/(1024*1024) -> 0 | R10: ='Datasize-Parameters'!$C$9 -> Credit | S10: 0 | T10: =S10*'Datasize-Parameters'!$D$24/(1024*1024) -> 0
B11: ='Datasize-Parameters'!$C$13 -> Facility | C11: 0 | D11: =C11*'Datasize-Parameters'!$D$24/(1024*1024) -> 0 | F11: ='Datasize-Parameters'!$C$13 -> Facility | G11: 0 | H11: =G11*'Datasize-Parameters'!$D$24/(1024*1024) -> 0 | J11: ='Datasize-Parameters'!$C$13 -> Facility | K11: 0 | L11: =K11*'Datasize-Parameters'!$D$24/(1024*1024) -> 0 | N11: ='Datasize-Parameters'!$C$13 -> Facility | O11: 0 | P11: =O11*'Datasize-Parameters'!$D$24/(1024*1024) -> 0 | R11: ='Datasize-Parameters'!$C$13 -> Facility | S11: 0 | T11: =S11*'Datasize-Parameters'!$D$24/(1024*1024) -> 0
B13: Total File Storage | D13: =SUM(D5:D11) -> 5349.591 | F13: Total File Storage | H13: =SUM(H5:H11) -> 5884.3059 | J13: Total File Storage | L13: =SUM(L5:L11) -> 6472.4802 | N13: Total File Storage | P13: =SUM(P5:P11) -> 7119.459 | R13: Total File Storage | T13: =SUM(T5:T11) -> 7831.1223
D14: Size in GB | H14: Size in GB | L14: Size in GB | P14: Size in GB | T14: Size in GB
B16: Disk File Storage (GB) | F16: Disk File Storage (GB) | J16: Disk File Storage (GB) | N16: Disk File Storage (GB) | R16: Disk File Storage (GB)
B18: Total Object Storage | D18: =D13 -> 5349.591 | F18: Total Object Storage | H18: =H13 -> 5884.3059 | J18: Total Object Storage | L18: =L13 -> 6472.4802 | N18: Total Object Storage | P18: =P13 -> 7119.459 | R18: Total Object Storage | T18: =T13 -> 7831.1223
B19: Temp File Storage | D19: =D18*10% -> 534.9591 | F19: Temp File Storage | H19: =H18*10% -> 588.43059 | J19: Temp File Storage | L19: =L18*10% -> 647.24802 | N19: Temp File Storage | P19: =P18*10% -> 711.9459 | R19: Temp File Storage | T19: =T18*10% -> 783.11223
B21: Total: 1st year | D21: =SUM(D18:D19) -> 5884.5501 | F21: Total: 2nd year | H21: =SUM(H18:H19) -> 6472.7365 | J21: Total: 3rd year | L21: =SUM(L18:L19) -> 7119.7282 | N21: Total: 4th year | P21: =SUM(P18:P19) -> 7831.4049 | R21: Total: 5th year | T21: =SUM(T18:T19) -> 8614.2345
D22: GB | H22: GB | L22: GB | P22: GB | T22: GB

Sheet Cloud sizing inputs
B2: Select Values here
B3: CSP | C3: Region | D3: No of AZs | E3: Year | F3: Database | G3: Database Option | H3: DB License type | I3: Reporting DB required | J3: Grafana-Prometheus & EFK reuired(Optional)
B4: GCP | C4: Mumbai | D4: 2 | E4: 5 | F4: Oracle Database | G4: Cloud Managed Database | H4: Cloud managed | I4: Yes | J4: Yes
B6: Data Table | D6: DO NOT TOUCH!!!
B7: Year | C7: Worker Nodes Linux/RHEL - CRMnext | D7: CRMnext Database Server vCPU | E7: Persistance DB Storage | F7: File Storage | H7: DB vCPU | I7: DB vCPU - Adjusted | M7: Parameter | N7: Get Value
B8: 1 | C8: ='server size'!#ref! -> #VALUE! | D8: =2*ROUND('Server size'!C22,1) -> 112 | E8: =ROUNDUP('Data size'!D30/50,0)*50 -> 2050 | F8: =ROUNDUP('DMS size'!D21/100,0)*100 -> 5900 | H8: 2 | I8: 8 | M8: Cloud Managed K8s | N8: =VLOOKUP(B4,B43:C45,2,FALSE()) -> GKE
B9: 2 | C9: ='server size'!#ref! -> #VALUE! | D9: =2*ROUND('Server size'!D22,1) -> 116 | E9: =ROUNDUP('Data size'!H30/50,0)*50 -> 2250 | F9: =ROUNDUP('DMS size'!H21/100,0)*100 -> 6500 | H9: 4 | I9: 8 | M9: Worker Nodes Linux/RHEL - CRMnext | N9: =VLOOKUP(E4,B8:F12,2,FALSE()) -> #VALUE!
B10: 3 | C10: ='server size'!#ref! -> #VALUE! | D10: =2*'Server size'!E22 -> 120 | E10: =ROUNDUP('Data size'!L30/50,0)*50 -> 2500 | F10: =ROUNDUP('DMS size'!L21/100,0)*100 -> 7200 | H10: 6 | I10: 8 | M10: CRMnext Database Server vCPU | N10: =VLOOKUP(E4,B8:F12,3,FALSE()) -> 132
B11: 4 | C11: ='server size'!#ref! -> #VALUE! | D11: =2*ROUND('Server size'!F22,1) -> 124 | E11: =ROUNDUP('Data size'!P30/50,0)*50 -> 2750 | F11: =ROUNDUP('DMS size'!P21/100,0)*100 -> 7900 | H11: 8 | I11: 8 | M11: CRMnext Database Server vCPU - Adjusted | N11: =VLOOKUP(N10,H8:I39,2,FALSE()) -> #N/A
B12: 5 | C12: ='server size'!#ref! -> #VALUE! | D12: =2*ROUND('Server size'!G22,1) -> 132 | E12: =ROUNDUP('Data size'!T30/50,0)*50 -> 3000 | F12: =ROUNDUP('DMS size'!T21/100,0)*100 -> 8700 | H12: 10 | I12: 8 | M12: Persistance DB Storage | N12: =VLOOKUP(E4,B8:F12,4,FALSE()) -> 3000
H13: 12 | I13: 16 | M13: File Storage | N13: =VLOOKUP(E4,B8:F12,5,FALSE()) -> 8700
B14: Data Table | D14: DO NOT TOUCH!!! | H14: 14 | I14: 16 | M14: Database Servers | N14: =VLOOKUP(F4&" "&G4,B16:E19,4,FALSE()) -> Cloud Managed Database
B15: DB servers helper | C15: Database | D15: Database Option | E15: Server | F15: License | H15: 16 | I15: 16 | M15: License | N15: =VLOOKUP(F4,C16:F17,4,FALSE()) -> Oracle License
B16: =C16&" "&D16 -> MS SQL Database DB on Nodes | C16: MS SQL Database | D16: DB on Nodes | E16: Windows Nodes | F16: SQL License | H16: 18 | I16: 16 | M16: Cloud Managed DB service | N16: =VLOOKUP(B4&" "&F4&" "&G4,B23:F34,5,FALSE()) -> Bare Metal Solution for Oracle
B17: =C17&" "&D17 -> Oracle Database DB on Nodes | C17: Oracle Database | D17: DB on Nodes | E17: Linux/RHEL Nodes | F17: Oracle License | H17: 20 | I17: 16 | M17: Persistance DB Storage IOPS | N17: =N12/100 -> 30
B18: =C18&" "&D18 -> MS SQL Database Cloud Managed Database | C18: MS SQL Database | D18: Cloud Managed Database | E18: Cloud Managed Database | H18: 22 | I18: 16 | M18: File Storage | N18: =VLOOKUP(B4,B43:D45,3,FALSE()) -> Cloud Storage
B19: =C19&" "&D19 -> Oracle Database Cloud Managed Database | C19: Oracle Database | D19: Cloud Managed Database | E19: Cloud Managed Database | H19: 24 | I19: 16 | M19: Redis | N19: =VLOOKUP(B4,B43:E45,4,FALSE()) -> MemoryStore
H20: 26 | I20: 32 | M20: Grafana-Prometheus & EFK Nodes | N20: =VLOOKUP(J4,B37:C39,2,FALSE()) -> 2
B21: Data Table | D21: DO NOT TOUCH!!! | H21: 28 | I21: 32 | M21: Reporting DB Nodes | N21: =VLOOKUP(I4,E38:F39,2,FALSE()) -> 1
B22: Cloud DB service helper | C22: CSP | D22: Database | E22: Database Option | F22: Cloud DB service | H22: 30 | I22: 32 | M22: Image Registry | N22: =VLOOKUP(B4,B43:F45,5,FALSE()) -> Artifact Registry
B23: =C23&" "&D23&" "&E23 -> AWS MS SQL Database DB on Nodes | C23: AWS | D23: MS SQL Database | E23: DB on Nodes | F23: Memory Optimized | H23: 32 | I23: 32 | M23: NAT Gateway | N23: =VLOOKUP(B4,B43:G45,6,FALSE()) -> Cloud NAT
B24: =C24&" "&D24&" "&E24 -> AWS Oracle Database DB on Nodes | C24: AWS | D24: Oracle Database | E24: DB on Nodes | F24: Memory Optimized | H24: 34 | I24: 32
B25: =C25&" "&D25&" "&E25 -> AWS MS SQL Database Cloud Managed Database | C25: AWS | D25: MS SQL Database | E25: Cloud Managed Database | F25: RDS | H25: 36 | I25: 32
B26: =C26&" "&D26&" "&E26 -> AWS Oracle Database Cloud Managed Database | C26: AWS | D26: Oracle Database | E26: Cloud Managed Database | F26: RDS | H26: 38 | I26: 32
B27: =C27&" "&D27&" "&E27 -> GCP MS SQL Database DB on Nodes | C27: GCP | D27: MS SQL Database | E27: DB on Nodes | F27: Memory Optimized | H27: 40 | I27: 32
B28: =C28&" "&D28&" "&E28 -> GCP Oracle Database DB on Nodes | C28: GCP | D28: Oracle Database | E28: DB on Nodes | F28: Memory Optimized | H28: 42 | I28: 64
B29: =C29&" "&D29&" "&E29 -> GCP MS SQL Database Cloud Managed Database | C29: GCP | D29: MS SQL Database | E29: Cloud Managed Database | F29: Cloud SQL | H29: 44 | I29: 64
B30: =C30&" "&D30&" "&E30 -> GCP Oracle Database Cloud Managed Database | C30: GCP | D30: Oracle Database | E30: Cloud Managed Database | F30: Bare Metal Solution for Oracle | H30: 46 | I30: 64
B31: =C31&" "&D31&" "&E31 -> Azure MS SQL Database DB on Nodes | C31: Azure | D31: MS SQL Database | E31: DB on Nodes | F31: Memory Optimized | H31: 48 | I31: 64
B32: =C32&" "&D32&" "&E32 -> Azure Oracle Database DB on Nodes | C32: Azure | D32: Oracle Database | E32: DB on Nodes | F32: Memory Optimized | H32: 50 | I32: 64
B33: =C33&" "&D33&" "&E33 -> Azure MS SQL Database Cloud Managed Database | C33: Azure | D33: MS SQL Database | E33: Cloud Managed Database | F33: Azure Database | H33: 52 | I33: 64
B34: =C34&" "&D34&" "&E34 -> Azure Oracle Database Cloud Managed Database | C34: Azure | D34: Oracle Database | E34: Cloud Managed Database | F34: Azure Database | H34: 54 | I34: 64
H35: 56 | I35: 64
H36: 58 | I36: 64
B37: Grafana-Prometheus & EFK reuired(Optional) | C37: Nodes | E37: Reporting DB required | F37: Nodes | H37: 60 | I37: 64
B38: Yes | C38: 2 | E38: Yes | F38: 1 | H38: 62 | I38: 64
B39: No | C39: 0 | E39: No | F39: 0 | H39: 64 | I39: 64
B42: CSP | C42: K8s | D42: Disk Storage | E42: Redis | F42: Image Registry | G42: NAT GW
B43: AWS | C43: EKS | D43: S3 | E43: Elasticache | F43: ECR | G43: NAT Gateway
B44: GCP | C44: GKE | D44: Cloud Storage | E44: MemoryStore | F44: Artifact Registry | G44: Cloud NAT
...

Sheet Cloud Sizing
C2: CSP | D2: Region | E2: Environment | F2: Year
C3: ='Cloud sizing inputs'!B4 -> GCP | D3: ='Cloud sizing inputs'!C4 -> Mumbai | E3: PROD | F3: ='Cloud sizing inputs'!E4 -> 5
B5: Services/Instances | C5: Nodes | D5: Type | E5: Pricing Model | F5: Per Node vCPU | G5: Per Node RAM (GB) | H5: Per Node Storage (GB) | I5: Total vCPU | J5: Total RAM (GB) | K5: Total Storage (TB)
B6: Kubernetes Cluster
B7: Cloud Managed K8s | C7: 1 | D7: ='Cloud sizing inputs'!N8 -> GKE
B8: Worker Nodes Linux/RHEL - CRMnext | C8: ='Cloud sizing inputs'!N9 -> #VALUE! | D8: Compute Intensive | E8: Reserved | F8: 16 | G8: 32 | H8: 300 | I8: =F8*C8 -> #VALUE! | J8: =G8*C8 -> #VALUE! | K8: =H8*C8/1024 -> #VALUE!
